Workbook

Sheet Sheet1(after xlookup)
A1: Title | B1: Lead Actor | C1: Director Name | D1: Lead Actor FB Likes | E1: Cast FB Likes | F1: Director FB Likes | G1: Movie FB Likes | H1: IMDb Score (1-10) | I1: Total Reviews | J1: Duration (min) | K1: Gross Revenue | L1: Budget | M1: {=_xlfn.XLOOKUP(A1,Sheet2!$A$1:$A$3726,Sheet2!$B$1:$G$3726)} -> Release Date | N1: Color/B&W | O1: Genre | P1: Language | Q1: Country | R1: Rating | S1: is_english | T1: Profit | U1: %Profit | V1: duration_class
A2: [Rec] 2 | B2: Jonathan D. Mellor | C2: Jaume BalaguerÃ³ | D2: 37 | E2: 73 | F2: 57 | G2: 4000 | H2: 6.6 | I2: 222 | J2: 85 | K2: 27024 | L2: 5600000 | M2: {=_xlfn.XLOOKUP(A2,Sheet2!$A$1:$A$3726,Sheet2!$B$1:$G$3726)} -> 39921 | N2: Color | O2: Horror | P2: Spanish | Q2: Spain | R2: R
A3: 10 Days in a Madhouse | B3: Christopher Lambert | C3: Timothy Hines | D3: 1000 | E3: 2059 | F3: 0 | G3: 26000 | H3: 7.5 | I3: 1 | J3: 111 | K3: 14616 | L3: 12000000 | M3: {=_xlfn.XLOOKUP(A3,Sheet2!$A$1:$A$3726,Sheet2!$B$1:$G$3726)} -> 42130 | N3: Color | O3: Drama | P3: English | Q3: USA | R3: R
A4: 10 Things I Hate About You | B4: Joseph Gordon-Levitt | C4: Gil Junger | D4: 23000 | E4: 37907 | F4: 19 | G4: 10000 | H4: 7.2 | I4: 133 | J4: 97 | K4: 38176108 | L4: 16000000 | M4: {=_xlfn.XLOOKUP(A4,Sheet2!$A$1:$A$3726,Sheet2!$B$1:$G$3726)} -> 36245 | N4: Color | O4: Comedy | P4: English | Q4: USA | R4: PG-13
A5: 102 Dalmatians | B5: Ioan Gruffudd | C5: Kevin Lima | D5: 2000 | E5: 4182 | F5: 36 | G5: 372 | H5: 4.8 | I5: 84 | J5: 100 | K5: 66941559 | L5: 85000000 | M5: {=_xlfn.XLOOKUP(A5,Sheet2!$A$1:$A$3726,Sheet2!$B$1:$G$3726)} -> 36715 | N5: Color | O5: Adventure | P5: English | Q5: USA | R5: G
A6: 10th & Wolf | B6: Brian Dennehy | C6: Robert Moresco | D6: 954 | E6: 2512 | F6: 53 | G6: 294 | H6: 6.4 | I6: 26 | J6: 107 | K6: 53481 | L6: 8000000 | M6: {=_xlfn.XLOOKUP(A6,Sheet2!$A$1:$A$3726,Sheet2!$B$1:$G$3726)} -> 38850 | N6: Color | O6: Crime | P6: English | Q6: USA | R6: R
A7: 12 Rounds | B7: Taylor Cole | C7: Renny Harlin | D7: 969 | E7: 2799 | F7: 212 | G7: 0 | H7: 5.6 | I7: 113 | J7: 108 | K7: 12232937 | L7: 22000000 | M7: {=_xlfn.XLOOKUP(A7,Sheet2!$A$1:$A$3726,Sheet2!$B$1:$G$3726)} -> 40137 | N7: Color | O7: Action | P7: English | Q7: USA | R7: PG-13
A8: 12 Years a Slave | B8: QuvenzhanÃ© Wallis | C8: Steve McQueen | D8: 2000 | E8: 4251 | F8: 0 | G8: 83000 | H8: 8.1 | I8: 597 | J8: 134 | K8: 56667870 | L8: 20000000 | M8: {=_xlfn.XLOOKUP(A8,Sheet2!$A$1:$A$3726,Sheet2!$B$1:$G$3726)} -> 41587 | N8: Color | O8: Biography | P8: English | Q8: USA | R8: R
A9: 127 Hours | B9: James Franco | C9: Danny Boyle | D9: 11000 | E9: 11984 | F9: 0 | G9: 63000 | H9: 7.6 | I9: 450 | J9: 94 | K9: 18329466 | L9: 18000000 | M9: {=_xlfn.XLOOKUP(A9,Sheet2!$A$1:$A$3726,Sheet2!$B$1:$G$3726)} -> 40312 | N9: Color | O9: Adventure | P9: English | Q9: USA | R9: R
A10: 13 Going on 30 | B10: Jennifer Garner | C10: Gary Winick | D10: 3000 | E10: 6742 | F10: 56 | G10: 0 | H10: 6.1 | I10: 119 | J10: 98 | K10: 56044241 | L10: 37000000 | M10: {=_xlfn.XLOOKUP(A10,Sheet2!$A$1:$A$3726,Sheet2!$B$1:$G$3726)} -> 38154 | N10: Color | O10: Comedy | P10: English | Q10: USA | R10: PG-13
A11: 1408 | B11: Drew Powell | C11: Mikael HÃ¥fstrÃ¶m | D11: 129 | E11: 214 | F11: 101 | G11: 11000 | H11: 6.8 | I11: 314 | J11: 114 | K11: 71975611 | L11: 25000000 | M11: {=_xlfn.XLOOKUP(A11,Sheet2!$A$1:$A$3726,Sheet2!$B$1:$G$3726)} -> 39152 | N11: Color | O11: Fantasy | P11: English | Q11: USA | R11: PG-13
A12: 15 Minutes | B12: Robert De Niro | C12: John Herzfeld | D12: 22000 | E12: 33585 | F12: 17 | G12: 748 | H12: 6.1 | I12: 151 | J12: 120 | K12: 24375436 | L12: 42000000 | M12: {=_xlfn.XLOOKUP(A12,Sheet2!$A$1:$A$3726,Sheet2!$B$1:$G$3726)} -> 36908 | N12: Color | O12: Action | P12: English | Q12: USA | R12: R
A13: 16 Blocks | B13: Bruce Willis | C13: Richard Donner | D13: 13000 | E13: 15053 | F13: 503 | G13: 0 | H13: 6.6 | I13: 199 | J13: 102 | K13: 36883539 | L13: 52000000 | M13: {=_xlfn.XLOOKUP(A13,Sheet2!$A$1:$A$3726,Sheet2!$B$1:$G$3726)} -> 39029 | N13: Color | O13: Action | P13: English | Q13: Germany | R13: PG-13
... A123: Abduction | B123: Ken Arnold | C123: John Singleton | D123: 327 | E123: 561 | F123: 309 | G123: 13000 | H123: 5 | I123: 180 | J123: 106 | K123: 28064226 | L123: 35000000 | M123: {=_xlfn.XLOOKUP(A123,Sheet2!$A$1:$A$3726,Sheet2!$B$1:$G$3726)} -> 40642 | N123: Color | O123: Action | P123: English | Q123: USA | R123: PG-13
A124: Aberdeen | B124: Charlotte Rampling | C124: Hans Petter Moland | D124: 844 | E124: 846 | F124: 19 | G124: 260 | H124: 7.3 | I124: 28 | J124: 106 | K124: 64148 | L124: 6500000 | M124: {=_xlfn.XLOOKUP(A124,Sheet2!$A$1:$A$3726,Sheet2!$B$1:$G$3726)} -> 36567 | N124: Color | O124: Drama | P124: English | Q124: UK | R124: 0
A125: About a Boy | B125: Sharon Small | C125: Chris Weitz | D125: 66 | E125: 74 | F125: 129 | G125: 0 | H125: 7.1 | I125: 158 | J125: 101 | K125: 40566655 | L125: 30000000 | M125: {=_xlfn.XLOOKUP(A125,Sheet2!$A$1:$A$3726,Sheet2!$B$1:$G$3726)} -> 37424 | N125: Color | O125: Comedy | P125: English | Q125: UK | R125: PG-13
A126: About Last Night | B126: Joe Lo Truglio | C126: Steve Pink | D126: 833 | E126: 2800 | F126: 38 | G126: 0 | H126: 6.1 | I126: 90 | J126: 100 | K126: 48637684 | L126: 12500000 | M126: {=_xlfn.XLOOKUP(A126,Sheet2!$A$1:$A$3726,Sheet2!$B$1:$G$3726)} -> 41713 | N126: Color | O126: Comedy | P126: English | Q126: USA | R126: R
A127: About Schmidt | B127: Hope Davis | C127: Alexander Payne | D127: 442 | E127: 1556 | F127: 729 | G127: 0 | H127: 7.2 | I127: 217 | J127: 125 | K127: 65010106 | L127: 30000000 | M127: {=_xlfn.XLOOKUP(A127,Sheet2!$A$1:$A$3726,Sheet2!$B$1:$G$3726)} -> 37405 | N127: Color | O127: Comedy | P127: English | Q127: USA | R127: R
A128: About Time | B128: Tom Hughes | C128: Richard Curtis | D128: 565 | E128: 1595 | F128: 628 | G128: 105000 | H128: 7.8 | I128: 274 | J128: 123 | K128: 15294553 | L128: 12000000 | M128: {=_xlfn.XLOOKUP(A128,Sheet2!$A$1:$A$3726,Sheet2!$B$1:$G$3726)} -> 41385 | N128: Color | O128: Drama | P128: English | Q128: UK | R128: R
A129: Abraham Lincoln: Vampire Hunter | B129: Rufus Sewell | C129: Timur Bekmambetov | D129: 3000 | E129: 8281 | F129: 335 | G129: 98000 | H129: 5.9 | I129: 393 | J129: 105 | K129: 37516013 | L129: 69000000 | M129: {=_xlfn.XLOOKUP(A129,Sheet2!$A$1:$A$3726,Sheet2!$B$1:$G$3726)} -> 41168 | N129: Color | O129: Action | P129: English | Q129: USA | R129: R
A130: Absolute Power | B130: Clint Eastwood | C130: Clint Eastwood | D130: 16000 | E130: 19139 | F130: 16000 | G130: 1000 | H130: 6.7 | I130: 76 | J130: 121 | K130: 50007168 | L130: 50000000 | M130: {=_xlfn.XLOOKUP(A130,Sheet2!$A$1:$A$3726,Sheet2!$B$1:$G$3726)} -> 35763 | N130: Color | O130: Action | P130: English | Q130: USA | R130: R
A131: Ace Ventura: Pet Detective | B131: Sean Young | C131: Tom Shadyac | D131: 759 | E131: 2462 | F131: 293 | G131: 0 | H131: 6.9 | I131: 61 | J131: 78 | K131: 72217000 | L131: 12000000 | M131: {=_xlfn.XLOOKUP(A131,Sheet2!$A$1:$A$3726,Sheet2!$B$1:$G$3726)} -> 34608 | N131: Color | O131: Comedy | P131: English | Q131: USA | R131: PG-13
A132: Ace Ventura: When Nature Calls | B132: Bruce Spence | C132: Steve Oedekerk | D132: 531 | E132: 2203 | F132: 176 | G132: 0 | H132: 6.3 | I132: 59 | J132: 90 | K132: 108360000 | L132: 30000000 | M132: {=_xlfn.XLOOKUP(A132,Sheet2!$A$1:$A$3726,Sheet2!$B$1:$G$3726)} -> 34981 | N132: Color | O132: Adventure | P132: English | Q132: USA | R132: PG-13
A133: Across the Universe | B133: Jim Sturgess | C133: Julie Taymor | D133: 5000 | E133: 5405 | F133: 278 | G133: 14000 | H133: 7.4 | I133: 156 | J133: 133 | K133: 24343673 | L133: 45000000 | M133: {=_xlfn.XLOOKUP(A133,Sheet2!$A$1:$A$3726,Sheet2!$B$1:$G$3726)} -> 39274 | N133: Color | O133: Drama | P133: English | Q133: USA | R133: PG-13
A134: Act of Valor | B134: Alex Veadov | C134: Mike McCoy | D134: 93 | E134: 146 | F134: 16 | G134: 15000 | H134: 6.5 | I134: 216 | J134: 110 | K134: 70011073 | L134: 12000000 | M134: {=_xlfn.XLOOKUP(A134,Sheet2!$A$1:$A$3726,Sheet2!$B$1:$G$3726)} -> 41194 | N134: Color | O134: Action | P134: English | Q134: USA | R134: R
A135: Action Jackson | B135: Bill Duke | C135: Craig R. Baxley | D135: 1000 | E135: 5282 | F135: 22 | G135: 978 | H135: 5.2 | I135: 35 | J135: 96 | K135: 20257000 | L135: 7000000 | M135: {=_xlfn.XLOOKUP(A135,Sheet2!$A$1:$A$3726,Sheet2!$B$1:$G$3726)} -> 32333 | N135: Color | O135: Action | P135: English | Q135: USA | R135: R
A136: Adaptation. | B136: Nicolas Cage | C136: Spike Jonze | D136: 12000 | E136: 25489 | F136: 0 | G136: 0 | H136: 7.7 | I136: 241 | J136: 81 | K136: 22245861 | L136: 19000000 | M136: {=_xlfn.XLOOKUP(A136,Sheet2!$A$1:$A$3726,Sheet2!$B$1:$G$3726)} -> 37359 | N136: Color | O136: Comedy | P136: English | Q136: USA | R136: R
... A146: Agora | B146: Max Minghella | C146: Alejandro AmenÃ¡bar | D146: 614 | E146: 1829 | F146: 448 | G146: 29000 | H146: 7.2 | I146: 180 | J146: 141 | K146: 617840 | L146: 70000000 | M146: {=_xlfn.XLOOKUP(A146,Sheet2!$A$1:$A$3726,Sheet2!$B$1:$G$3726)} -> 39874 | N146: Color | O146: Adventure | P146: English | Q146: Spain | R146: R
A147: Aimee & Jaguar | B147: Heike Makatsch | C147: Max FÃ¤rberbÃ¶ck | D147: 177 | E147: 333 | F147: 4 | G147: 687 | H147: 7.3 | I147: 63 | J147: 125 | K147: 927107 | L147: 15000000 | M147: {=_xlfn.XLOOKUP(A147,Sheet2!$A$1:$A$3726,Sheet2!$B$1:$G$3726)} -> 36455 | N147: Color | O147: Biography | P147: German | Q147: Germany | R147: 0
A148: Air Bud | B148: Kevin Zegers | C148: Charles Martin Smith | D148: 2000 | E148: 4277 | F148: 188 | G148: 902 | H148: 5.1 | I148: 35 | J148: 98 | K148: 24629916 | L148: 3000000 | M148: {=_xlfn.XLOOKUP(A148,Sheet2!$A$1:$A$3726,Sheet2!$B$1:$G$3726)} -> 35717 | N148: Color | O148: Comedy | P148: English | Q148: USA | R148: PG
A149: Air Force One | B149: Harrison Ford | C149: Wolfgang Petersen | D149: 11000 | E149: 23603 | F149: 249 | G149: 0 | H149: 6.4 | I149: 142 | J149: 124 | K149: 172620724 | L149: 85000000 | M149: {=_xlfn.XLOOKUP(A149,Sheet2!$A$1:$A$3726,Sheet2!$B$1:$G$3726)} -> 35541 | N149: Color | O149: Action | P149: English | Q149: USA | R149: R
A150: Airborne | B150: Alanna Ubach | C150: Rob Bowman | D150: 584 | E150: 1218 | F150: 38 | G150: 0 | H150: 6.2 | I150: 9 | J150: 91 | K150: 2850263 | L150: 2600000 | M150: {=_xlfn.XLOOKUP(A150,Sheet2!$A$1:$A$3726,Sheet2!$B$1:$G$3726)} -> 34221 | N150: Color | O150: Adventure | P150: English | Q150: USA | R150: PG
A151: Airplane! | B151: Peter Graves | C151: Jim Abrahams | D151: 628 | E151: 2726 | F151: 104 | G151: 16000 | H151: 7.8 | I151: 134 | J151: 88 | K151: 83400000 | L151: 3500000 | M151: {=_xlfn.XLOOKUP(A151,Sheet2!$A$1:$A$3726,Sheet2!$B$1:$G$3726)} -> 29411 | N151: Color | O151: Comedy | P151: English | Q151: USA | R151: PG
A152: Akira | B152: Mitsuo Iwata | C152: Katsuhiro Ã”tomo | D152: 6 | E152: 28 | F152: 78 | G152: 0 | H152: 8.1 | I152: 150 | J152: 124 | K152: 439162 | L152: 1100000000 | M152: {=_xlfn.XLOOKUP(A152,Sheet2!$A$1:$A$3726,Sheet2!$B$1:$G$3726)} -> 32491 | N152: Color | O152: Action | P152: Japanese | Q152: Japan | R152: R
A153: Aladdin | B153: Robin Williams | C153: Ron Clements | D153: 49000 | E153: 52970 | F153: 63 | G153: 0 | H153: 8 | I153: 124 | J153: 90 | K153: 217350219 | L153: 28000000 | M153: {=_xlfn.XLOOKUP(A153,Sheet2!$A$1:$A$3726,Sheet2!$B$1:$G$3726)} -> 33910 | N153: Color | O153: Adventure | P153: English | Q153: USA | R153: G
A154: Albert Nobbs | B154: Mia Wasikowska | C154: Rodrigo GarcÃ­a | D154: 3000 | E154: 4370 | F154: 127 | G154: 0 | H154: 6.7 | I154: 222 | J154: 113 | K154: 3014541 | L154: 8000000 | M154: {=_xlfn.XLOOKUP(A154,Sheet2!$A$1:$A$3726,Sheet2!$B$1:$G$3726)} -> 40558 | N154: Color | O154: Drama | P154: English | Q154: UK | R154: R
A155: Albino Alligator | B155: Viggo Mortensen | C155: Kevin Spacey | D155: 10000 | E155: 13718 | F155: 18000 | G155: 225 | H155: 6.1 | I155: 37 | J155: 97 | K155: 326308 | L155: 5000000 | M155: {=_xlfn.XLOOKUP(A155,Sheet2!$A$1:$A$3726,Sheet2!$B$1:$G$3726)} -> 35428 | N155: Color | O155: Crime | P155: English | Q155: USA | R155: R
A156: Alex & Emma | B156: David Paymer | C156: Rob Reiner | D156: 372 | E156: 977 | F156: 0 | G156: 625 | H156: 5.6 | I156: 73 | J156: 96 | K156: 14208384 | L156: 30000000 | M156: {=_xlfn.XLOOKUP(A156,Sheet2!$A$1:$A$3726,Sheet2!$B$1:$G$3726)} -> 37798 | N156: Color | O156: Comedy | P156: English | Q156: USA | R156: PG-13
A157: Alex Cross | B157: Cicely Tyson | C157: Rob Cohen | D157: 907 | E157: 2471 | F157: 357 | G157: 11000 | H157: 5.1 | I157: 211 | J157: 101 | K157: 25863915 | L157: 35000000 | M157: {=_xlfn.XLOOKUP(A157,Sheet2!$A$1:$A$3726,Sheet2!$B$1:$G$3726)} -> 41154 | N157: Color | O157: Action | P157: English | Q157: USA | R157: PG-13
A158: Alex Rider: Operation Stormbreaker | B158: Alex Pettyfer | C158: Geoffrey Sax | D158: 15000 | E158: 15638 | F158: 13 | G158: 823 | H158: 5.1 | I158: 66 | J158: 93 | K158: 652526 | L158: 40000000 | M158: {=_xlfn.XLOOKUP(A158,Sheet2!$A$1:$A$3726,Sheet2!$B$1:$G$3726)} -> 38793 | N158: Color | O158: Action | P158: English | Q158: Germany | R158: PG
...

Sheet Sheet2
A1: Title | B1: Release Date | C1: Color/B&W | D1: Genre | E1: Language | F1: Country | G1: Rating
A2: Justin Bieber: Never Say Never | B2: 40795 | C2: Color | D2: Documentary | E2: English | F2: USA | G2: G
A3: Superbabies: Baby Geniuses 2 | B3: 37997 | C3: Color | D3: Comedy | E3: English | F3: Germany | G3: PG
A4: Disaster Movie | B4: 39500 | C4: Color | D4: Comedy | E4: English | F4: USA | G4: PG-13
A5: Who's Your Caddy? | B5: 39417 | C5: Color | D5: Comedy | E5: English | F5: USA | G5: PG-13
A6: Glitter | B6: 36928 | C6: Color | D6: Drama | E6: English | F6: USA | G6: PG-13
A7: From Justin to Kelly | B7: 37642 | C7: Color | D7: Comedy | E7: English | F7: USA | G7: PG
A8: Crossover | B8: 38816 | C8: Color | D8: Action | E8: English | F8: USA | G8: PG-13
A9: Son of the Mask | B9: 38368 | C9: Color | D9: Comedy | E9: English | F9: USA | G9: PG
A10: Chairman of the Board | B10: 35973 | C10: Color | D10: Comedy | E10: English | F10: USA | G10: PG-13
A11: Alone in the Dark | B11: 38455 | C11: Color | D11: Horror | E11: English | F11: Canada | G11: R
A12: Epic Movie | B12: 39362 | C12: Color | D12: Adventure | E12: English | F12: USA | G12: PG-13
A13: Gigli | B13: 37722 | C13: Color | D13: Comedy | E13: English | F13: USA | G13: R
... A35: Police Academy: Mission to Moscow | B35: 34520 | C35: Color | D35: Comedy | E35: English | F35: USA | G35: PG
A36: Neal 'N' Nikki | B36: 38661 | C36: Color | D36: Comedy | E36: English | F36: India
A37: Bucky Larson: Born to Be a Star | B37: 40727 | C37: Color | D37: Comedy | E37: English | F37: USA | G37: R
A38: Ocean's Eleven | B38: 37222 | C38: Color | D38: Crime | E38: English | F38: USA | G38: PG-13
A39: Catwoman | B39: 38290 | C39: Color | D39: Action | E39: English | F39: USA | G39: PG-13
A40: The Book of Mormon Movie, Volume 1: The Journey | B40: 37755 | C40: Color | D40: Adventure | E40: English | F40: USA | G40: PG-13
A41: Spice World | B41: 35445 | C41: Color | D41: Comedy | E41: English | F41: UK | G41: PG
A42: The Master of Disguise | B42: 37532 | C42: Color | D42: Comedy | E42: English | F42: USA | G42: PG
A43: Crossroads | B43: 37484 | C43: Color | D43: Comedy | E43: English | F43: USA | G43: PG-13
A44: Jack and Jill | B44: 40815 | C44: Color | D44: Comedy | E44: English | F44: USA | G44: PG
A45: Dumb and Dumberer: When Harry Met Lloyd | B45: 37839 | C45: Color | D45: Comedy | E45: English | F45: USA | G45: PG-13
A46: An Alan Smithee Film: Burn Hollywood Burn | B46: 35558 | C46: Color | D46: Comedy | E46: English | F46: USA | G46: R
A47: Megaforce | B47: 30012 | C47: Color | D47: Action | E47: English | F47: USA | G47: PG
A48: The Adventures of Sharkboy and Lavagirl 3-D | B48: 38546 | C48: Color | D48: Action | E48: English | F48: USA | G48: PG
... A215: Monkeybone | B215: 37044 | C215: Color | D215: Animation | E215: English | F215: USA | G215: PG-13
A216: Gory Gory Hallelujah | B216: 37952 | C216: Color | D216: Comedy | E216: English | F216: USA
A217: Turbulence | B217: 35451 | C217: Color | D217: Action | E217: English | F217: USA | G217: R
A218: Raise the Titanic | B218: 29480 | C218: Color | D218: Action | E218: English | F218: UK | G218: PG
A219: Jonah Hex | B219: 40260 | C219: Color | D219: Action | E219: English | F219: USA | G219: PG-13
A220: Did You Hear About the Morgans? | B220: 39960 | C220: Color | D220: Comedy | E220: English | F220: USA | G220: PG-13
A221: The Next Best Thing | B221: 36627 | C221: Color | D221: Comedy | E221: English | F221: USA | G221: PG-13
A222: Hanging Up | B222: 36859 | C222: Color | D222: Comedy | E222: English | F222: Germany | G222: PG-13
A223: The Musketeer | B223: 36935 | C223: Color | D223: Action | E223: English | F223: Germany | G223: PG-13
A224: The Marine | B224: 39059 | C224: Color | D224: Action | E224: English | F224: USA | G224: PG-13
A225: Pulse | B225: 38798 | C225: Color | D225: Drama | E225: English | F225: USA | G225: PG-13
A226: Aliens vs. Predator: Requiem | B226: 39249 | C226: Color | D226: Action | E226: English | F226: USA | G226: R
A227: Full Frontal | B227: 37344 | C227: Color | D227: Comedy | E227: English | F227: USA | G227: R
...
